<?xml version='1.0' encoding='UTF-8'?>
<robot xmlns:xacro="http://ros.org/wiki/xacro" name="100129">
  <xacro:macro name="100129" params="ns_prefix parent joint_type xyz rpy scale_x scale_y scale_z mesh_dir">
    <link name="${ns_prefix}_link_0">
      <visual name="rotation_lid-3">
        <origin xyz="${-0.11440558821760938 * scale_x} ${-0.2886859015583081 * scale_y} ${0.42 * scale_z}"/>
        <geometry>
          <mesh filename="package://scene_builder/${mesh_dir}/textured_objs/original-2.obj" scale="${scale_x} ${scale_y} ${scale_z}"/>
        </geometry>
      </visual>
      <collision>
        <origin xyz="${-0.11440558821760938 * scale_x} ${-0.2886859015583081 * scale_y} ${0.42 * scale_z}"/>
        <geometry>
          <mesh filename="package://scene_builder/${mesh_dir}/textured_objs/original-2.obj" scale="${scale_x} ${scale_y} ${scale_z}"/>
        </geometry>
      </collision>
    </link>
    <joint name="${ns_prefix}_joint_0" type="revolute">
      <origin xyz="${0.11440558821760938 * scale_x} ${0.2886859015583081 * scale_y} ${-0.42 * scale_z}"/>
      <axis xyz="-0.644123314889653 0 0"/>
      <child link="${ns_prefix}_link_0"/>
      <parent link="${ns_prefix}"/>
      <limit lower="-2.2689280275926285" upper="0.5235987755982988" effort="0.0" velocity="0.5"/>
    </joint>
    <link name="${ns_prefix}_link_1">
      <visual name="rotation_lid-4">
        <origin xyz="${-0.427809 * scale_x} ${-0.288 * scale_y} ${-0.43565743326573825 * scale_z}"/>
        <geometry>
          <mesh filename="package://scene_builder/${mesh_dir}/textured_objs/original-1.obj" scale="${scale_x} ${scale_y} ${scale_z}"/>
        </geometry>
      </visual>
      <collision>
        <origin xyz="${-0.427809 * scale_x} ${-0.288 * scale_y} ${-0.43565743326573825 * scale_z}"/>
        <geometry>
          <mesh filename="package://scene_builder/${mesh_dir}/textured_objs/original-1.obj" scale="${scale_x} ${scale_y} ${scale_z}"/>
        </geometry>
      </collision>
    </link>
    <joint name="${ns_prefix}_joint_1" type="revolute">
      <origin xyz="${0.427809 * scale_x} ${0.288 * scale_y} ${0.43565743326573825 * scale_z}"/>
      <axis xyz="1 0 0"/>
      <child link="${ns_prefix}_link_1"/>
      <parent link="${ns_prefix}"/>
      <limit lower="-2.0943951023931953" upper="0.6981317007977318" effort="0.0" velocity="0.5"/>
    </joint>
    <link name="${ns_prefix}">
      <visual name="base_body-6">
        <origin xyz="0 0 0"/>
        <geometry>
          <mesh filename="package://scene_builder/${mesh_dir}/textured_objs/original-26.obj" scale="${scale_x} ${scale_y} ${scale_z}"/>
        </geometry>
      </visual>
      <visual name="base_body-6">
        <origin xyz="0 0 0"/>
        <geometry>
          <mesh filename="package://scene_builder/${mesh_dir}/textured_objs/original-3.obj" scale="${scale_x} ${scale_y} ${scale_z}"/>
        </geometry>
      </visual>
      <collision>
        <origin xyz="0 0 0"/>
        <geometry>
          <mesh filename="package://scene_builder/${mesh_dir}/textured_objs/original-26.obj" scale="${scale_x} ${scale_y} ${scale_z}"/>
        </geometry>
      </collision>
      <collision>
        <origin xyz="0 0 0"/>
        <geometry>
          <mesh filename="package://scene_builder/${mesh_dir}/textured_objs/original-3.obj" scale="${scale_x} ${scale_y} ${scale_z}"/>
        </geometry>
      </collision>
    </link>
    <joint name="${ns_prefix}_joint_2" type="${joint_type}">
      <origin rpy="${rpy}" xyz="${xyz}"/>
      <child link="${ns_prefix}"/>
      <parent link="${parent}"/>
    </joint>
  </xacro:macro>
</robot>
