<?xml version="1.0" ?>
<robot name="partnet_0d31000f-e876-4751-876d-efa6a61fa9b2">
	<link name="base"/>
	<link name="link_0">
		<visual name="door-1">
			<origin xyz="0.3599005086719992 0 -0.3731304919719703"/>
			<geometry>
				<mesh filename="textured_objs/original-8.obj"/>
			</geometry>
		</visual>
		<visual name="door-1">
			<origin xyz="0.3599005086719992 0 -0.3731304919719703"/>
			<geometry>
				<mesh filename="textured_objs/original-25.obj"/>
			</geometry>
		</visual>
		<visual name="door-1">
			<origin xyz="0.3599005086719992 0 -0.3731304919719703"/>
			<geometry>
				<mesh filename="textured_objs/original-23.obj"/>
			</geometry>
		</visual>
		<visual name="door-1">
			<origin xyz="0.3599005086719992 0 -0.3731304919719703"/>
			<geometry>
				<mesh filename="textured_objs/original-24.obj"/>
			</geometry>
		</visual>
		<collision>
			<origin xyz="0.3599005086719992 0 -0.3731304919719703"/>
			<geometry>
				<mesh filename="textured_objs/original-8.obj"/>
			</geometry>
		</collision>
		<collision>
			<origin xyz="0.3599005086719992 0 -0.3731304919719703"/>
			<geometry>
				<mesh filename="textured_objs/original-25.obj"/>
			</geometry>
		</collision>
		<collision>
			<origin xyz="0.3599005086719992 0 -0.3731304919719703"/>
			<geometry>
				<mesh filename="textured_objs/original-23.obj"/>
			</geometry>
		</collision>
		<collision>
			<origin xyz="0.3599005086719992 0 -0.3731304919719703"/>
			<geometry>
				<mesh filename="textured_objs/original-24.obj"/>
			</geometry>
		</collision>
	</link>
	<joint name="joint_0" type="revolute">
		<origin xyz="-0.3599005086719992 0 0.3731304919719703"/>
		<axis xyz="0 -1 0"/>
		<child link="link_0"/>
		<parent link="link_11"/>
		<limit lower="-0.0" upper="1.5707963267948966"/>
	</joint>
	<link name="link_1">
		<visual name="button-2">
			<origin xyz="-0.3542036780733284 -0.39688577832783684 0.05753293603676607"/>
			<geometry>
				<mesh filename="textured_objs/original-72.obj"/>
			</geometry>
		</visual>
		<collision>
			<origin xyz="-0.3542036780733284 -0.39688577832783684 0.05753293603676607"/>
			<geometry>
				<mesh filename="textured_objs/original-72.obj"/>
			</geometry>
		</collision>
	</link>
	<joint name="joint_1" type="prismatic">
		<origin xyz="0.3542036780733284 0.39688577832783684 -0.05753293603676607"/>
		<axis xyz="-0.00037048643998581975 -0.143137599586484 -0.9897027282595605"/>
		<child link="link_1"/>
		<parent link="link_11"/>
		<limit lower="0" upper="0.0020000000000000035"/>
	</joint>
	<link name="link_2">
		<visual name="button-3">
			<origin xyz="-0.35419985431689943 -0.41903548256741646 0.06217514871659105"/>
			<geometry>
				<mesh filename="textured_objs/original-71.obj"/>
			</geometry>
		</visual>
		<collision>
			<origin xyz="-0.35419985431689943 -0.41903548256741646 0.06217514871659105"/>
			<geometry>
				<mesh filename="textured_objs/original-71.obj"/>
			</geometry>
		</collision>
	</link>
	<joint name="joint_2" type="prismatic">
		<origin xyz="0.35419985431689943 0.41903548256741646 -0.06217514871659105"/>
		<axis xyz="-0.0003762627441764139 -0.14645877669005733 -0.9892167028294656"/>
		<child link="link_2"/>
		<parent link="link_11"/>
		<limit lower="0" upper="0.002"/>
	</joint>
	<link name="link_3">
		<visual name="button-4">
			<origin xyz="-0.35402759078678026 -0.3940501227852911 0.09424717233999408"/>
			<geometry>
				<mesh filename="textured_objs/original-74.obj"/>
			</geometry>
		</visual>
		<collision>
			<origin xyz="-0.35402759078678026 -0.3940501227852911 0.09424717233999408"/>
			<geometry>
				<mesh filename="textured_objs/original-74.obj"/>
			</geometry>
		</collision>
	</link>
	<joint name="joint_3" type="prismatic">
		<origin xyz="0.35402759078678026 0.3940501227852911 -0.09424717233999408"/>
		<axis xyz="-0.0006850061797788022 -0.2320325298844645 -0.9727077854329885"/>
		<child link="link_3"/>
		<parent link="link_11"/>
		<limit lower="0" upper="0.002"/>
	</joint>
	<link name="link_4">
		<visual name="button-5">
			<origin xyz="-0.18337024708212274 -0.344960322480346 0.08379129244212552"/>
			<geometry>
				<mesh filename="textured_objs/original-73.obj"/>
			</geometry>
		</visual>
		<collision>
			<origin xyz="-0.18337024708212274 -0.344960322480346 0.08379129244212552"/>
			<geometry>
				<mesh filename="textured_objs/original-73.obj"/>
			</geometry>
		</collision>
	</link>
	<joint name="joint_4" type="prismatic">
		<origin xyz="0.18337024708212274 0.344960322480346 -0.08379129244212552"/>
		<axis xyz="-0.0005071592872327467 -0.23578318456498037 -0.9718055529095591"/>
		<child link="link_4"/>
		<parent link="link_11"/>
		<limit lower="0" upper="0.002"/>
	</joint>
	<link name="link_5">
		<visual name="button-6">
			<origin xyz="-0.1833545929245808 -0.3660701972614527 0.0903342712877245"/>
			<geometry>
				<mesh filename="textured_objs/original-69.obj"/>
			</geometry>
		</visual>
		<collision>
			<origin xyz="-0.1833545929245808 -0.3660701972614527 0.0903342712877245"/>
			<geometry>
				<mesh filename="textured_objs/original-69.obj"/>
			</geometry>
		</collision>
	</link>
	<joint name="joint_5" type="prismatic">
		<origin xyz="0.1833545929245808 0.3660701972614527 -0.0903342712877245"/>
		<axis xyz="-0.0005326473723436396 -0.23932934421925803 -0.9709382994209039"/>
		<child link="link_5"/>
		<parent link="link_11"/>
		<limit lower="0" upper="0.0020000000000000035"/>
	</joint>
	<link name="link_6">
		<visual name="button-7">
			<origin xyz="0.008761399268019521 -0.41806335956566504 0.03209614388720258"/>
			<geometry>
				<mesh filename="textured_objs/original-93.obj"/>
			</geometry>
		</visual>
		<collision>
			<origin xyz="0.008761399268019521 -0.41806335956566504 0.03209614388720258"/>
			<geometry>
				<mesh filename="textured_objs/original-93.obj"/>
			</geometry>
		</collision>
	</link>
	<joint name="joint_6" type="continuous">
		<origin xyz="-0.008761399268019521 0.41806335956566504 -0.03209614388720258"/>
		<axis xyz="4.957299135578828e-05 0.0765491623286357 0.9970658069000776"/>
		<child link="link_6"/>
		<parent link="link_11"/>
	</joint>
	<link name="link_7">
		<visual name="button-9">
			<origin xyz="-0.35854121100699893 -0.26971246098145457 0.07943172551970044"/>
			<geometry>
				<mesh filename="textured_objs/original-54.obj"/>
			</geometry>
		</visual>
		<collision>
			<origin xyz="-0.35854121100699893 -0.26971246098145457 0.07943172551970044"/>
			<geometry>
				<mesh filename="textured_objs/original-54.obj"/>
			</geometry>
		</collision>
	</link>
	<joint name="joint_7" type="prismatic">
		<origin xyz="0.35854121100699893 0.26971246098145457 -0.07943172551970044"/>
		<axis xyz="-0.0006150225540038502 -0.2817560248174122 -0.9594858853710918"/>
		<child link="link_7"/>
		<parent link="link_11"/>
		<limit lower="0" upper="0.0020000000000000035"/>
	</joint>
	<link name="link_8">
		<visual name="button-10">
			<origin xyz="-0.2981777964465463 -0.2698431240783992 0.07943287019957479"/>
			<geometry>
				<mesh filename="textured_objs/original-56.obj"/>
			</geometry>
		</visual>
		<collision>
			<origin xyz="-0.2981777964465463 -0.2698431240783992 0.07943287019957479"/>
			<geometry>
				<mesh filename="textured_objs/original-56.obj"/>
			</geometry>
		</collision>
	</link>
	<joint name="joint_8" type="prismatic">
		<origin xyz="0.2981777964465463 0.2698431240783992 -0.07943287019957479"/>
		<axis xyz="-0.0006197430653554141 -0.28175601330820277 -0.959485885713386"/>
		<child link="link_8"/>
		<parent link="link_11"/>
		<limit lower="0" upper="0.0020000000000000035"/>
	</joint>
	<link name="link_9">
		<visual name="button-11">
			<origin xyz="-0.2378157967575946 -0.2699742646473275 0.07943239151948361"/>
			<geometry>
				<mesh filename="textured_objs/original-55.obj"/>
			</geometry>
		</visual>
		<collision>
			<origin xyz="-0.2378157967575946 -0.2699742646473275 0.07943239151948361"/>
			<geometry>
				<mesh filename="textured_objs/original-55.obj"/>
			</geometry>
		</collision>
	</link>
	<joint name="joint_9" type="prismatic">
		<origin xyz="0.2378157967575946 0.2699742646473275 -0.07943239151948361"/>
		<axis xyz="-0.0006197430653554136 -0.2817560133082028 -0.959485885713386"/>
		<child link="link_9"/>
		<parent link="link_11"/>
		<limit lower="0" upper="0.0020000000000000035"/>
	</joint>
	<link name="link_10">
		<visual name="button-12">
			<origin xyz="-0.1776042849361452 -0.33738368134295027 0.055611193944969245"/>
			<geometry>
				<mesh filename="textured_objs/original-57.obj"/>
			</geometry>
		</visual>
		<collision>
			<origin xyz="-0.1776042849361452 -0.33738368134295027 0.055611193944969245"/>
			<geometry>
				<mesh filename="textured_objs/original-57.obj"/>
			</geometry>
		</collision>
	</link>
	<joint name="joint_10" type="prismatic">
		<origin xyz="0.1776042849361452 0.33738368134295027 -0.055611193944969245"/>
		<axis xyz="-0.00035732740387698795 -0.1624530396388856 -0.9867162115974448"/>
		<child link="link_10"/>
		<parent link="link_11"/>
		<limit lower="0" upper="0.0020000000000000035"/>
	</joint>
	<link name="link_11">
		<visual name="base_body-13">
			<origin xyz="0 0 0"/>
			<geometry>
				<mesh filename="textured_objs/original-29.obj"/>
			</geometry>
		</visual>
		<visual name="base_body-13">
			<origin xyz="0 0 0"/>
			<geometry>
				<mesh filename="textured_objs/original-103.obj"/>
			</geometry>
		</visual>
		<visual name="base_body-13">
			<origin xyz="0 0 0"/>
			<geometry>
				<mesh filename="textured_objs/original-100.obj"/>
			</geometry>
		</visual>
		<visual name="base_body-13">
			<origin xyz="0 0 0"/>
			<geometry>
				<mesh filename="textured_objs/original-123.obj"/>
			</geometry>
		</visual>
		<visual name="base_body-13">
			<origin xyz="0 0 0"/>
			<geometry>
				<mesh filename="textured_objs/original-21.obj"/>
			</geometry>
		</visual>
		<visual name="base_body-13">
			<origin xyz="0 0 0"/>
			<geometry>
				<mesh filename="textured_objs/original-208.obj"/>
			</geometry>
		</visual>
		<visual name="base_body-13">
			<origin xyz="0 0 0"/>
			<geometry>
				<mesh filename="textured_objs/original-30.obj"/>
			</geometry>
		</visual>
		<visual name="base_body-13">
			<origin xyz="0 0 0"/>
			<geometry>
				<mesh filename="textured_objs/original-152.obj"/>
			</geometry>
		</visual>
		<visual name="base_body-13">
			<origin xyz="0 0 0"/>
			<geometry>
				<mesh filename="textured_objs/original-132.obj"/>
			</geometry>
		</visual>
		<visual name="base_body-13">
			<origin xyz="0 0 0"/>
			<geometry>
				<mesh filename="textured_objs/original-236.obj"/>
			</geometry>
		</visual>
		<visual name="base_body-13">
			<origin xyz="0 0 0"/>
			<geometry>
				<mesh filename="textured_objs/original-36.obj"/>
			</geometry>
		</visual>
		<visual name="base_body-13">
			<origin xyz="0 0 0"/>
			<geometry>
				<mesh filename="textured_objs/original-154.obj"/>
			</geometry>
		</visual>
		<visual name="base_body-13">
			<origin xyz="0 0 0"/>
			<geometry>
				<mesh filename="textured_objs/original-249.obj"/>
			</geometry>
		</visual>
		<visual name="base_body-13">
			<origin xyz="0 0 0"/>
			<geometry>
				<mesh filename="textured_objs/original-126.obj"/>
			</geometry>
		</visual>
		<visual name="base_body-13">
			<origin xyz="0 0 0"/>
			<geometry>
				<mesh filename="textured_objs/original-169.obj"/>
			</geometry>
		</visual>
		<visual name="base_body-13">
			<origin xyz="0 0 0"/>
			<geometry>
				<mesh filename="textured_objs/original-198.obj"/>
			</geometry>
		</visual>
		<visual name="base_body-13">
			<origin xyz="0 0 0"/>
			<geometry>
				<mesh filename="textured_objs/original-278.obj"/>
			</geometry>
		</visual>
		<visual name="base_body-13">
			<origin xyz="0 0 0"/>
			<geometry>
				<mesh filename="textured_objs/original-119.obj"/>
			</geometry>
		</visual>
		<visual name="base_body-13">
			<origin xyz="0 0 0"/>
			<geometry>
				<mesh filename="textured_objs/original-188.obj"/>
			</geometry>
		</visual>
		<visual name="base_body-13">
			<origin xyz="0 0 0"/>
			<geometry>
				<mesh filename="textured_objs/original-28.obj"/>
			</geometry>
		</visual>
		<visual name="base_body-13">
			<origin xyz="0 0 0"/>
			<geometry>
				<mesh filename="textured_objs/original-283.obj"/>
			</geometry>
		</visual>
		<visual name="base_body-13">
			<origin xyz="0 0 0"/>
			<geometry>
				<mesh filename="textured_objs/original-124.obj"/>
			</geometry>
		</visual>
		<visual name="base_body-13">
			<origin xyz="0 0 0"/>
			<geometry>
				<mesh filename="textured_objs/original-230.obj"/>
			</geometry>
		</visual>
		<visual name="base_body-13">
			<origin xyz="0 0 0"/>
			<geometry>
				<mesh filename="textured_objs/original-166.obj"/>
			</geometry>
		</visual>
		<visual name="base_body-13">
			<origin xyz="0 0 0"/>
			<geometry>
				<mesh filename="textured_objs/original-224.obj"/>
			</geometry>
		</visual>
		<visual name="base_body-13">
			<origin xyz="0 0 0"/>
			<geometry>
				<mesh filename="textured_objs/original-195.obj"/>
			</geometry>
		</visual>
		<visual name="base_body-13">
			<origin xyz="0 0 0"/>
			<geometry>
				<mesh filename="textured_objs/original-64.obj"/>
			</geometry>
		</visual>
		<visual name="base_body-13">
			<origin xyz="0 0 0"/>
			<geometry>
				<mesh filename="textured_objs/original-134.obj"/>
			</geometry>
		</visual>
		<visual name="base_body-13">
			<origin xyz="0 0 0"/>
			<geometry>
				<mesh filename="textured_objs/original-263.obj"/>
			</geometry>
		</visual>
		<visual name="base_body-13">
			<origin xyz="0 0 0"/>
			<geometry>
				<mesh filename="textured_objs/original-192.obj"/>
			</geometry>
		</visual>
		<visual name="base_body-13">
			<origin xyz="0 0 0"/>
			<geometry>
				<mesh filename="textured_objs/original-43.obj"/>
			</geometry>
		</visual>
		<visual name="base_body-13">
			<origin xyz="0 0 0"/>
			<geometry>
				<mesh filename="textured_objs/original-167.obj"/>
			</geometry>
		</visual>
		<visual name="base_body-13">
			<origin xyz="0 0 0"/>
			<geometry>
				<mesh filename="textured_objs/original-272.obj"/>
			</geometry>
		</visual>
		<visual name="base_body-13">
			<origin xyz="0 0 0"/>
			<geometry>
				<mesh filename="textured_objs/original-193.obj"/>
			</geometry>
		</visual>
		<visual name="base_body-13">
			<origin xyz="0 0 0"/>
			<geometry>
				<mesh filename="textured_objs/original-196.obj"/>
			</geometry>
		</visual>
		<visual name="base_body-13">
			<origin xyz="0 0 0"/>
			<geometry>
				<mesh filename="textured_objs/original-199.obj"/>
			</geometry>
		</visual>
		<visual name="base_body-13">
			<origin xyz="0 0 0"/>
			<geometry>
				<mesh filename="textured_objs/original-83.obj"/>
			</geometry>
		</visual>
		<visual name="base_body-13">
			<origin xyz="0 0 0"/>
			<geometry>
				<mesh filename="textured_objs/original-117.obj"/>
			</geometry>
		</visual>
		<visual name="base_body-13">
			<origin xyz="0 0 0"/>
			<geometry>
				<mesh filename="textured_objs/original-110.obj"/>
			</geometry>
		</visual>
		<visual name="base_body-13">
			<origin xyz="0 0 0"/>
			<geometry>
				<mesh filename="textured_objs/original-153.obj"/>
			</geometry>
		</visual>
		<visual name="base_body-13">
			<origin xyz="0 0 0"/>
			<geometry>
				<mesh filename="textured_objs/original-107.obj"/>
			</geometry>
		</visual>
		<visual name="base_body-13">
			<origin xyz="0 0 0"/>
			<geometry>
				<mesh filename="textured_objs/original-160.obj"/>
			</geometry>
		</visual>
		<visual name="base_body-13">
			<origin xyz="0 0 0"/>
			<geometry>
				<mesh filename="textured_objs/original-222.obj"/>
			</geometry>
		</visual>
		<visual name="base_body-13">
			<origin xyz="0 0 0"/>
			<geometry>
				<mesh filename="textured_objs/original-104.obj"/>
			</geometry>
		</visual>
		<visual name="base_body-13">
			<origin xyz="0 0 0"/>
			<geometry>
				<mesh filename="textured_objs/original-4.obj"/>
			</geometry>
		</visual>
		<visual name="base_body-13">
			<origin xyz="0 0 0"/>
			<geometry>
				<mesh filename="textured_objs/original-149.obj"/>
			</geometry>
		</visual>
		<visual name="base_body-13">
			<origin xyz="0 0 0"/>
			<geometry>
				<mesh filename="textured_objs/original-3.obj"/>
			</geometry>
		</visual>
		<visual name="base_body-13">
			<origin xyz="0 0 0"/>
			<geometry>
				<mesh filename="textured_objs/original-128.obj"/>
			</geometry>
		</visual>
		<visual name="base_body-13">
			<origin xyz="0 0 0"/>
			<geometry>
				<mesh filename="textured_objs/original-260.obj"/>
			</geometry>
		</visual>
		<visual name="base_body-13">
			<origin xyz="0 0 0"/>
			<geometry>
				<mesh filename="textured_objs/original-65.obj"/>
			</geometry>
		</visual>
		<visual name="base_body-13">
			<origin xyz="0 0 0"/>
			<geometry>
				<mesh filename="textured_objs/original-130.obj"/>
			</geometry>
		</visual>
		<visual name="base_body-13">
			<origin xyz="0 0 0"/>
			<geometry>
				<mesh filename="textured_objs/original-137.obj"/>
			</geometry>
		</visual>
		<visual name="base_body-13">
			<origin xyz="0 0 0"/>
			<geometry>
				<mesh filename="textured_objs/original-139.obj"/>
			</geometry>
		</visual>
		<visual name="base_body-13">
			<origin xyz="0 0 0"/>
			<geometry>
				<mesh filename="textured_objs/original-44.obj"/>
			</geometry>
		</visual>
		<visual name="base_body-13">
			<origin xyz="0 0 0"/>
			<geometry>
				<mesh filename="textured_objs/original-112.obj"/>
			</geometry>
		</visual>
		<visual name="base_body-13">
			<origin xyz="0 0 0"/>
			<geometry>
				<mesh filename="textured_objs/original-162.obj"/>
			</geometry>
		</visual>
		<visual name="base_body-13">
			<origin xyz="0 0 0"/>
			<geometry>
				<mesh filename="textured_objs/original-106.obj"/>
			</geometry>
		</visual>
		<visual name="base_body-13">
			<origin xyz="0 0 0"/>
			<geometry>
				<mesh filename="textured_objs/original-16.obj"/>
			</geometry>
		</visual>
		<visual name="base_body-13">
			<origin xyz="0 0 0"/>
			<geometry>
				<mesh filename="textured_objs/original-251.obj"/>
			</geometry>
		</visual>
		<visual name="base_body-13">
			<origin xyz="0 0 0"/>
			<geometry>
				<mesh filename="textured_objs/original-86.obj"/>
			</geometry>
		</visual>
		<visual name="base_body-13">
			<origin xyz="0 0 0"/>
			<geometry>
				<mesh filename="textured_objs/original-173.obj"/>
			</geometry>
		</visual>
		<visual name="base_body-13">
			<origin xyz="0 0 0"/>
			<geometry>
				<mesh filename="textured_objs/original-140.obj"/>
			</geometry>
		</visual>
		<visual name="base_body-13">
			<origin xyz="0 0 0"/>
			<geometry>
				<mesh filename="textured_objs/original-147.obj"/>
			</geometry>
		</visual>
		<visual name="base_body-13">
			<origin xyz="0 0 0"/>
			<geometry>
				<mesh filename="textured_objs/original-109.obj"/>
			</geometry>
		</visual>
		<visual name="base_body-13">
			<origin xyz="0 0 0"/>
			<geometry>
				<mesh filename="textured_objs/original-259.obj"/>
			</geometry>
		</visual>
		<visual name="base_body-13">
			<origin xyz="0 0 0"/>
			<geometry>
				<mesh filename="textured_objs/original-13.obj"/>
			</geometry>
		</visual>
		<visual name="base_body-13">
			<origin xyz="0 0 0"/>
			<geometry>
				<mesh filename="textured_objs/original-210.obj"/>
			</geometry>
		</visual>
		<visual name="base_body-13">
			<origin xyz="0 0 0"/>
			<geometry>
				<mesh filename="textured_objs/original-268.obj"/>
			</geometry>
		</visual>
		<visual name="base_body-13">
			<origin xyz="0 0 0"/>
			<geometry>
				<mesh filename="textured_objs/original-9.obj"/>
			</geometry>
		</visual>
		<visual name="base_body-13">
			<origin xyz="0 0 0"/>
			<geometry>
				<mesh filename="textured_objs/original-125.obj"/>
			</geometry>
		</visual>
		<visual name="base_body-13">
			<origin xyz="0 0 0"/>
			<geometry>
				<mesh filename="textured_objs/original-35.obj"/>
			</geometry>
		</visual>
		<visual name="base_body-13">
			<origin xyz="0 0 0"/>
			<geometry>
				<mesh filename="textured_objs/original-267.obj"/>
			</geometry>
		</visual>
		<visual name="base_body-13">
			<origin xyz="0 0 0"/>
			<geometry>
				<mesh filename="textured_objs/original-279.obj"/>
			</geometry>
		</visual>
		<visual name="base_body-13">
			<origin xyz="0 0 0"/>
			<geometry>
				<mesh filename="textured_objs/original-138.obj"/>
			</geometry>
		</visual>
		<visual name="base_body-13">
			<origin xyz="0 0 0"/>
			<geometry>
				<mesh filename="textured_objs/original-156.obj"/>
			</geometry>
		</visual>
		<visual name="base_body-13">
			<origin xyz="0 0 0"/>
			<geometry>
				<mesh filename="textured_objs/original-201.obj"/>
			</geometry>
		</visual>
		<visual name="base_body-13">
			<origin xyz="0 0 0"/>
			<geometry>
				<mesh filename="textured_objs/original-286.obj"/>
			</geometry>
		</visual>
		<visual name="base_body-13">
			<origin xyz="0 0 0"/>
			<geometry>
				<mesh filename="textured_objs/original-184.obj"/>
			</geometry>
		</visual>
		<visual name="base_body-13">
			<origin xyz="0 0 0"/>
			<geometry>
				<mesh filename="textured_objs/original-144.obj"/>
			</geometry>
		</visual>
		<visual name="base_body-13">
			<origin xyz="0 0 0"/>
			<geometry>
				<mesh filename="textured_objs/original-255.obj"/>
			</geometry>
		</visual>
		<visual name="base_body-13">
			<origin xyz="0 0 0"/>
			<geometry>
				<mesh filename="textured_objs/original-120.obj"/>
			</geometry>
		</visual>
		<visual name="base_body-13">
			<origin xyz="0 0 0"/>
			<geometry>
				<mesh filename="textured_objs/original-59.obj"/>
			</geometry>
		</visual>
		<visual name="base_body-13">
			<origin xyz="0 0 0"/>
			<geometry>
				<mesh filename="textured_objs/original-114.obj"/>
			</geometry>
		</visual>
		<visual name="base_body-13">
			<origin xyz="0 0 0"/>
			<geometry>
				<mesh filename="textured_objs/original-275.obj"/>
			</geometry>
		</visual>
		<visual name="base_body-13">
			<origin xyz="0 0 0"/>
			<geometry>
				<mesh filename="textured_objs/original-241.obj"/>
			</geometry>
		</visual>
		<visual name="base_body-13">
			<origin xyz="0 0 0"/>
			<geometry>
				<mesh filename="textured_objs/original-223.obj"/>
			</geometry>
		</visual>
		<visual name="base_body-13">
			<origin xyz="0 0 0"/>
			<geometry>
				<mesh filename="textured_objs/original-150.obj"/>
			</geometry>
		</visual>
		<visual name="base_body-13">
			<origin xyz="0 0 0"/>
			<geometry>
				<mesh filename="textured_objs/original-239.obj"/>
			</geometry>
		</visual>
		<visual name="base_body-13">
			<origin xyz="0 0 0"/>
			<geometry>
				<mesh filename="textured_objs/original-221.obj"/>
			</geometry>
		</visual>
		<visual name="base_body-13">
			<origin xyz="0 0 0"/>
			<geometry>
				<mesh filename="textured_objs/original-168.obj"/>
			</geometry>
		</visual>
		<visual name="base_body-13">
			<origin xyz="0 0 0"/>
			<geometry>
				<mesh filename="textured_objs/original-63.obj"/>
			</geometry>
		</visual>
		<visual name="base_body-13">
			<origin xyz="0 0 0"/>
			<geometry>
				<mesh filename="textured_objs/original-214.obj"/>
			</geometry>
		</visual>
		<visual name="base_body-13">
			<origin xyz="0 0 0"/>
			<geometry>
				<mesh filename="textured_objs/original-240.obj"/>
			</geometry>
		</visual>
		<visual name="base_body-13">
			<origin xyz="0 0 0"/>
			<geometry>
				<mesh filename="textured_objs/original-185.obj"/>
			</geometry>
		</visual>
		<visual name="base_body-13">
			<origin xyz="0 0 0"/>
			<geometry>
				<mesh filename="textured_objs/original-217.obj"/>
			</geometry>
		</visual>
		<visual name="base_body-13">
			<origin xyz="0 0 0"/>
			<geometry>
				<mesh filename="textured_objs/original-261.obj"/>
			</geometry>
		</visual>
		<visual name="base_body-13">
			<origin xyz="0 0 0"/>
			<geometry>
				<mesh filename="textured_objs/original-27.obj"/>
			</geometry>
		</visual>
		<visual name="base_body-13">
			<origin xyz="0 0 0"/>
			<geometry>
				<mesh filename="textured_objs/original-159.obj"/>
			</geometry>
		</visual>
		<visual name="base_body-13">
			<origin xyz="0 0 0"/>
			<geometry>
				<mesh filename="textured_objs/original-247.obj"/>
			</geometry>
		</visual>
		<visual name="base_body-13">
			<origin xyz="0 0 0"/>
			<geometry>
				<mesh filename="textured_objs/original-170.obj"/>
			</geometry>
		</visual>
		<visual name="base_body-13">
			<origin xyz="0 0 0"/>
			<geometry>
				<mesh filename="textured_objs/original-269.obj"/>
			</geometry>
		</visual>
		<visual name="base_body-13">
			<origin xyz="0 0 0"/>
			<geometry>
				<mesh filename="textured_objs/original-216.obj"/>
			</geometry>
		</visual>
		<visual name="base_body-13">
			<origin xyz="0 0 0"/>
			<geometry>
				<mesh filename="textured_objs/original-87.obj"/>
			</geometry>
		</visual>
		<visual name="base_body-13">
			<origin xyz="0 0 0"/>
			<geometry>
				<mesh filename="textured_objs/original-51.obj"/>
			</geometry>
		</visual>
		<visual name="base_body-13">
			<origin xyz="0 0 0"/>
			<geometry>
				<mesh filename="textured_objs/original-212.obj"/>
			</geometry>
		</visual>
		<visual name="base_body-13">
			<origin xyz="0 0 0"/>
			<geometry>
				<mesh filename="textured_objs/original-163.obj"/>
			</geometry>
		</visual>
		<visual name="base_body-13">
			<origin xyz="0 0 0"/>
			<geometry>
				<mesh filename="textured_objs/original-113.obj"/>
			</geometry>
		</visual>
		<visual name="base_body-13">
			<origin xyz="0 0 0"/>
			<geometry>
				<mesh filename="textured_objs/original-237.obj"/>
			</geometry>
		</visual>
		<visual name="base_body-13">
			<origin xyz="0 0 0"/>
			<geometry>
				<mesh filename="textured_objs/original-50.obj"/>
			</geometry>
		</visual>
		<visual name="base_body-13">
			<origin xyz="0 0 0"/>
			<geometry>
				<mesh filename="textured_objs/original-141.obj"/>
			</geometry>
		</visual>
		<visual name="base_body-13">
			<origin xyz="0 0 0"/>
			<geometry>
				<mesh filename="textured_objs/original-213.obj"/>
			</geometry>
		</visual>
		<visual name="base_body-13">
			<origin xyz="0 0 0"/>
			<geometry>
				<mesh filename="textured_objs/original-111.obj"/>
			</geometry>
		</visual>
		<visual name="base_body-13">
			<origin xyz="0 0 0"/>
			<geometry>
				<mesh filename="textured_objs/original-282.obj"/>
			</geometry>
		</visual>
		<visual name="base_body-13">
			<origin xyz="0 0 0"/>
			<geometry>
				<mesh filename="textured_objs/original-245.obj"/>
			</geometry>
		</visual>
		<visual name="base_body-13">
			<origin xyz="0 0 0"/>
			<geometry>
				<mesh filename="textured_objs/original-287.obj"/>
			</geometry>
		</visual>
		<visual name="base_body-13">
			<origin xyz="0 0 0"/>
			<geometry>
				<mesh filename="textured_objs/original-244.obj"/>
			</geometry>
		</visual>
		<visual name="base_body-13">
			<origin xyz="0 0 0"/>
			<geometry>
				<mesh filename="textured_objs/original-31.obj"/>
			</geometry>
		</visual>
		<visual name="base_body-13">
			<origin xyz="0 0 0"/>
			<geometry>
				<mesh filename="textured_objs/original-187.obj"/>
			</geometry>
		</visual>
		<visual name="base_body-13">
			<origin xyz="0 0 0"/>
			<geometry>
				<mesh filename="textured_objs/original-218.obj"/>
			</geometry>
		</visual>
		<visual name="base_body-13">
			<origin xyz="0 0 0"/>
			<geometry>
				<mesh filename="textured_objs/original-178.obj"/>
			</geometry>
		</visual>
		<visual name="base_body-13">
			<origin xyz="0 0 0"/>
			<geometry>
				<mesh filename="textured_objs/original-37.obj"/>
			</geometry>
		</visual>
		<visual name="base_body-13">
			<origin xyz="0 0 0"/>
			<geometry>
				<mesh filename="textured_objs/original-48.obj"/>
			</geometry>
		</visual>
		<visual name="base_body-13">
			<origin xyz="0 0 0"/>
			<geometry>
				<mesh filename="textured_objs/original-15.obj"/>
			</geometry>
		</visual>
		<visual name="base_body-13">
			<origin xyz="0 0 0"/>
			<geometry>
				<mesh filename="textured_objs/original-85.obj"/>
			</geometry>
		</visual>
		<visual name="base_body-13">
			<origin xyz="0 0 0"/>
			<geometry>
				<mesh filename="textured_objs/original-258.obj"/>
			</geometry>
		</visual>
		<visual name="base_body-13">
			<origin xyz="0 0 0"/>
			<geometry>
				<mesh filename="textured_objs/original-177.obj"/>
			</geometry>
		</visual>
		<visual name="base_body-13">
			<origin xyz="0 0 0"/>
			<geometry>
				<mesh filename="textured_objs/original-122.obj"/>
			</geometry>
		</visual>
		<visual name="base_body-13">
			<origin xyz="0 0 0"/>
			<geometry>
				<mesh filename="textured_objs/original-219.obj"/>
			</geometry>
		</visual>
		<visual name="base_body-13">
			<origin xyz="0 0 0"/>
			<geometry>
				<mesh filename="textured_objs/original-135.obj"/>
			</geometry>
		</visual>
		<visual name="base_body-13">
			<origin xyz="0 0 0"/>
			<geometry>
				<mesh filename="textured_objs/original-76.obj"/>
			</geometry>
		</visual>
		<visual name="base_body-13">
			<origin xyz="0 0 0"/>
			<geometry>
				<mesh filename="textured_objs/original-108.obj"/>
			</geometry>
		</visual>
		<visual name="base_body-13">
			<origin xyz="0 0 0"/>
			<geometry>
				<mesh filename="textured_objs/original-175.obj"/>
			</geometry>
		</visual>
		<visual name="base_body-13">
			<origin xyz="0 0 0"/>
			<geometry>
				<mesh filename="textured_objs/original-186.obj"/>
			</geometry>
		</visual>
		<visual name="base_body-13">
			<origin xyz="0 0 0"/>
			<geometry>
				<mesh filename="textured_objs/original-253.obj"/>
			</geometry>
		</visual>
		<visual name="base_body-13">
			<origin xyz="0 0 0"/>
			<geometry>
				<mesh filename="textured_objs/original-207.obj"/>
			</geometry>
		</visual>
		<visual name="base_body-13">
			<origin xyz="0 0 0"/>
			<geometry>
				<mesh filename="textured_objs/original-99.obj"/>
			</geometry>
		</visual>
		<visual name="base_body-13">
			<origin xyz="0 0 0"/>
			<geometry>
				<mesh filename="textured_objs/original-136.obj"/>
			</geometry>
		</visual>
		<visual name="base_body-13">
			<origin xyz="0 0 0"/>
			<geometry>
				<mesh filename="textured_objs/original-243.obj"/>
			</geometry>
		</visual>
		<visual name="base_body-13">
			<origin xyz="0 0 0"/>
			<geometry>
				<mesh filename="textured_objs/original-127.obj"/>
			</geometry>
		</visual>
		<visual name="base_body-13">
			<origin xyz="0 0 0"/>
			<geometry>
				<mesh filename="textured_objs/original-62.obj"/>
			</geometry>
		</visual>
		<visual name="base_body-13">
			<origin xyz="0 0 0"/>
			<geometry>
				<mesh filename="textured_objs/original-75.obj"/>
			</geometry>
		</visual>
		<visual name="base_body-13">
			<origin xyz="0 0 0"/>
			<geometry>
				<mesh filename="textured_objs/original-174.obj"/>
			</geometry>
		</visual>
		<visual name="base_body-13">
			<origin xyz="0 0 0"/>
			<geometry>
				<mesh filename="textured_objs/original-274.obj"/>
			</geometry>
		</visual>
		<visual name="base_body-13">
			<origin xyz="0 0 0"/>
			<geometry>
				<mesh filename="textured_objs/original-227.obj"/>
			</geometry>
		</visual>
		<visual name="base_body-13">
			<origin xyz="0 0 0"/>
			<geometry>
				<mesh filename="textured_objs/original-254.obj"/>
			</geometry>
		</visual>
		<visual name="base_body-13">
			<origin xyz="0 0 0"/>
			<geometry>
				<mesh filename="textured_objs/original-209.obj"/>
			</geometry>
		</visual>
		<visual name="base_body-13">
			<origin xyz="0 0 0"/>
			<geometry>
				<mesh filename="textured_objs/original-158.obj"/>
			</geometry>
		</visual>
		<visual name="base_body-13">
			<origin xyz="0 0 0"/>
			<geometry>
				<mesh filename="textured_objs/original-66.obj"/>
			</geometry>
		</visual>
		<visual name="base_body-13">
			<origin xyz="0 0 0"/>
			<geometry>
				<mesh filename="textured_objs/original-182.obj"/>
			</geometry>
		</visual>
		<visual name="base_body-13">
			<origin xyz="0 0 0"/>
			<geometry>
				<mesh filename="textured_objs/original-226.obj"/>
			</geometry>
		</visual>
		<visual name="base_body-13">
			<origin xyz="0 0 0"/>
			<geometry>
				<mesh filename="textured_objs/original-211.obj"/>
			</geometry>
		</visual>
		<visual name="base_body-13">
			<origin xyz="0 0 0"/>
			<geometry>
				<mesh filename="textured_objs/original-58.obj"/>
			</geometry>
		</visual>
		<visual name="base_body-13">
			<origin xyz="0 0 0"/>
			<geometry>
				<mesh filename="textured_objs/original-145.obj"/>
			</geometry>
		</visual>
		<visual name="base_body-13">
			<origin xyz="0 0 0"/>
			<geometry>
				<mesh filename="textured_objs/original-98.obj"/>
			</geometry>
		</visual>
		<visual name="base_body-13">
			<origin xyz="0 0 0"/>
			<geometry>
				<mesh filename="textured_objs/original-11.obj"/>
			</geometry>
		</visual>
		<visual name="base_body-13">
			<origin xyz="0 0 0"/>
			<geometry>
				<mesh filename="textured_objs/original-131.obj"/>
			</geometry>
		</visual>
		<visual name="base_body-13">
			<origin xyz="0 0 0"/>
			<geometry>
				<mesh filename="textured_objs/original-242.obj"/>
			</geometry>
		</visual>
		<visual name="base_body-13">
			<origin xyz="0 0 0"/>
			<geometry>
				<mesh filename="textured_objs/original-68.obj"/>
			</geometry>
		</visual>
		<visual name="base_body-13">
			<origin xyz="0 0 0"/>
			<geometry>
				<mesh filename="textured_objs/original-146.obj"/>
			</geometry>
		</visual>
		<visual name="base_body-13">
			<origin xyz="0 0 0"/>
			<geometry>
				<mesh filename="textured_objs/original-80.obj"/>
			</geometry>
		</visual>
		<visual name="base_body-13">
			<origin xyz="0 0 0"/>
			<geometry>
				<mesh filename="textured_objs/original-235.obj"/>
			</geometry>
		</visual>
		<visual name="base_body-13">
			<origin xyz="0 0 0"/>
			<geometry>
				<mesh filename="textured_objs/original-264.obj"/>
			</geometry>
		</visual>
		<visual name="base_body-13">
			<origin xyz="0 0 0"/>
			<geometry>
				<mesh filename="textured_objs/original-190.obj"/>
			</geometry>
		</visual>
		<visual name="base_body-13">
			<origin xyz="0 0 0"/>
			<geometry>
				<mesh filename="textured_objs/original-18.obj"/>
			</geometry>
		</visual>
		<visual name="base_body-13">
			<origin xyz="0 0 0"/>
			<geometry>
				<mesh filename="textured_objs/original-70.obj"/>
			</geometry>
		</visual>
		<visual name="base_body-13">
			<origin xyz="0 0 0"/>
			<geometry>
				<mesh filename="textured_objs/original-161.obj"/>
			</geometry>
		</visual>
		<visual name="base_body-13">
			<origin xyz="0 0 0"/>
			<geometry>
				<mesh filename="textured_objs/original-189.obj"/>
			</geometry>
		</visual>
		<visual name="base_body-13">
			<origin xyz="0 0 0"/>
			<geometry>
				<mesh filename="textured_objs/original-118.obj"/>
			</geometry>
		</visual>
		<visual name="base_body-13">
			<origin xyz="0 0 0"/>
			<geometry>
				<mesh filename="textured_objs/original-225.obj"/>
			</geometry>
		</visual>
		<visual name="base_body-13">
			<origin xyz="0 0 0"/>
			<geometry>
				<mesh filename="textured_objs/original-91.obj"/>
			</geometry>
		</visual>
		<visual name="base_body-13">
			<origin xyz="0 0 0"/>
			<geometry>
				<mesh filename="textured_objs/original-203.obj"/>
			</geometry>
		</visual>
		<visual name="base_body-13">
			<origin xyz="0 0 0"/>
			<geometry>
				<mesh filename="textured_objs/original-250.obj"/>
			</geometry>
		</visual>
		<visual name="base_body-13">
			<origin xyz="0 0 0"/>
			<geometry>
				<mesh filename="textured_objs/original-17.obj"/>
			</geometry>
		</visual>
		<visual name="base_body-13">
			<origin xyz="0 0 0"/>
			<geometry>
				<mesh filename="textured_objs/original-202.obj"/>
			</geometry>
		</visual>
		<visual name="base_body-13">
			<origin xyz="0 0 0"/>
			<geometry>
				<mesh filename="textured_objs/original-12.obj"/>
			</geometry>
		</visual>
		<visual name="base_body-13">
			<origin xyz="0 0 0"/>
			<geometry>
				<mesh filename="textured_objs/original-277.obj"/>
			</geometry>
		</visual>
		<visual name="base_body-13">
			<origin xyz="0 0 0"/>
			<geometry>
				<mesh filename="textured_objs/original-183.obj"/>
			</geometry>
		</visual>
		<visual name="base_body-13">
			<origin xyz="0 0 0"/>
			<geometry>
				<mesh filename="textured_objs/original-281.obj"/>
			</geometry>
		</visual>
		<visual name="base_body-13">
			<origin xyz="0 0 0"/>
			<geometry>
				<mesh filename="textured_objs/original-265.obj"/>
			</geometry>
		</visual>
		<visual name="base_body-13">
			<origin xyz="0 0 0"/>
			<geometry>
				<mesh filename="textured_objs/original-228.obj"/>
			</geometry>
		</visual>
		<visual name="base_body-13">
			<origin xyz="0 0 0"/>
			<geometry>
				<mesh filename="textured_objs/original-171.obj"/>
			</geometry>
		</visual>
		<visual name="base_body-13">
			<origin xyz="0 0 0"/>
			<geometry>
				<mesh filename="textured_objs/original-142.obj"/>
			</geometry>
		</visual>
		<visual name="base_body-13">
			<origin xyz="0 0 0"/>
			<geometry>
				<mesh filename="textured_objs/original-42.obj"/>
			</geometry>
		</visual>
		<visual name="base_body-13">
			<origin xyz="0 0 0"/>
			<geometry>
				<mesh filename="textured_objs/original-79.obj"/>
			</geometry>
		</visual>
		<visual name="base_body-13">
			<origin xyz="0 0 0"/>
			<geometry>
				<mesh filename="textured_objs/original-257.obj"/>
			</geometry>
		</visual>
		<visual name="base_body-13">
			<origin xyz="0 0 0"/>
			<geometry>
				<mesh filename="textured_objs/original-165.obj"/>
			</geometry>
		</visual>
		<visual name="base_body-13">
			<origin xyz="0 0 0"/>
			<geometry>
				<mesh filename="textured_objs/original-102.obj"/>
			</geometry>
		</visual>
		<visual name="base_body-13">
			<origin xyz="0 0 0"/>
			<geometry>
				<mesh filename="textured_objs/original-20.obj"/>
			</geometry>
		</visual>
		<visual name="base_body-13">
			<origin xyz="0 0 0"/>
			<geometry>
				<mesh filename="textured_objs/original-88.obj"/>
			</geometry>
		</visual>
		<visual name="base_body-13">
			<origin xyz="0 0 0"/>
			<geometry>
				<mesh filename="textured_objs/original-191.obj"/>
			</geometry>
		</visual>
		<visual name="base_body-13">
			<origin xyz="0 0 0"/>
			<geometry>
				<mesh filename="textured_objs/original-32.obj"/>
			</geometry>
		</visual>
		<visual name="base_body-13">
			<origin xyz="0 0 0"/>
			<geometry>
				<mesh filename="textured_objs/original-47.obj"/>
			</geometry>
		</visual>
		<visual name="base_body-13">
			<origin xyz="0 0 0"/>
			<geometry>
				<mesh filename="textured_objs/original-206.obj"/>
			</geometry>
		</visual>
		<visual name="base_body-13">
			<origin xyz="0 0 0"/>
			<geometry>
				<mesh filename="textured_objs/original-95.obj"/>
			</geometry>
		</visual>
		<visual name="base_body-13">
			<origin xyz="0 0 0"/>
			<geometry>
				<mesh filename="textured_objs/original-197.obj"/>
			</geometry>
		</visual>
		<visual name="base_body-13">
			<origin xyz="0 0 0"/>
			<geometry>
				<mesh filename="textured_objs/original-200.obj"/>
			</geometry>
		</visual>
		<visual name="base_body-13">
			<origin xyz="0 0 0"/>
			<geometry>
				<mesh filename="textured_objs/original-105.obj"/>
			</geometry>
		</visual>
		<visual name="base_body-13">
			<origin xyz="0 0 0"/>
			<geometry>
				<mesh filename="textured_objs/original-101.obj"/>
			</geometry>
		</visual>
		<visual name="base_body-13">
			<origin xyz="0 0 0"/>
			<geometry>
				<mesh filename="textured_objs/original-180.obj"/>
			</geometry>
		</visual>
		<visual name="base_body-13">
			<origin xyz="0 0 0"/>
			<geometry>
				<mesh filename="textured_objs/original-1.obj"/>
			</geometry>
		</visual>
		<visual name="base_body-13">
			<origin xyz="0 0 0"/>
			<geometry>
				<mesh filename="textured_objs/original-233.obj"/>
			</geometry>
		</visual>
		<visual name="base_body-13">
			<origin xyz="0 0 0"/>
			<geometry>
				<mesh filename="textured_objs/original-81.obj"/>
			</geometry>
		</visual>
		<visual name="base_body-13">
			<origin xyz="0 0 0"/>
			<geometry>
				<mesh filename="textured_objs/original-84.obj"/>
			</geometry>
		</visual>
		<visual name="base_body-13">
			<origin xyz="0 0 0"/>
			<geometry>
				<mesh filename="textured_objs/original-271.obj"/>
			</geometry>
		</visual>
		<visual name="base_body-13">
			<origin xyz="0 0 0"/>
			<geometry>
				<mesh filename="textured_objs/original-94.obj"/>
			</geometry>
		</visual>
		<visual name="base_body-13">
			<origin xyz="0 0 0"/>
			<geometry>
				<mesh filename="textured_objs/original-280.obj"/>
			</geometry>
		</visual>
		<visual name="base_body-13">
			<origin xyz="0 0 0"/>
			<geometry>
				<mesh filename="textured_objs/original-97.obj"/>
			</geometry>
		</visual>
		<visual name="base_body-13">
			<origin xyz="0 0 0"/>
			<geometry>
				<mesh filename="textured_objs/original-252.obj"/>
			</geometry>
		</visual>
		<visual name="base_body-13">
			<origin xyz="0 0 0"/>
			<geometry>
				<mesh filename="textured_objs/original-157.obj"/>
			</geometry>
		</visual>
		<visual name="base_body-13">
			<origin xyz="0 0 0"/>
			<geometry>
				<mesh filename="textured_objs/original-89.obj"/>
			</geometry>
		</visual>
		<visual name="base_body-13">
			<origin xyz="0 0 0"/>
			<geometry>
				<mesh filename="textured_objs/original-179.obj"/>
			</geometry>
		</visual>
		<visual name="base_body-13">
			<origin xyz="0 0 0"/>
			<geometry>
				<mesh filename="textured_objs/original-10.obj"/>
			</geometry>
		</visual>
		<visual name="base_body-13">
			<origin xyz="0 0 0"/>
			<geometry>
				<mesh filename="textured_objs/original-231.obj"/>
			</geometry>
		</visual>
		<visual name="base_body-13">
			<origin xyz="0 0 0"/>
			<geometry>
				<mesh filename="textured_objs/original-14.obj"/>
			</geometry>
		</visual>
		<visual name="base_body-13">
			<origin xyz="0 0 0"/>
			<geometry>
				<mesh filename="textured_objs/original-232.obj"/>
			</geometry>
		</visual>
		<visual name="base_body-13">
			<origin xyz="0 0 0"/>
			<geometry>
				<mesh filename="textured_objs/original-215.obj"/>
			</geometry>
		</visual>
		<visual name="base_body-13">
			<origin xyz="0 0 0"/>
			<geometry>
				<mesh filename="textured_objs/original-82.obj"/>
			</geometry>
		</visual>
		<visual name="base_body-13">
			<origin xyz="0 0 0"/>
			<geometry>
				<mesh filename="textured_objs/original-129.obj"/>
			</geometry>
		</visual>
		<visual name="base_body-13">
			<origin xyz="0 0 0"/>
			<geometry>
				<mesh filename="textured_objs/original-60.obj"/>
			</geometry>
		</visual>
		<visual name="base_body-13">
			<origin xyz="0 0 0"/>
			<geometry>
				<mesh filename="textured_objs/original-204.obj"/>
			</geometry>
		</visual>
		<visual name="base_body-13">
			<origin xyz="0 0 0"/>
			<geometry>
				<mesh filename="textured_objs/original-229.obj"/>
			</geometry>
		</visual>
		<visual name="base_body-13">
			<origin xyz="0 0 0"/>
			<geometry>
				<mesh filename="textured_objs/original-19.obj"/>
			</geometry>
		</visual>
		<visual name="base_body-13">
			<origin xyz="0 0 0"/>
			<geometry>
				<mesh filename="textured_objs/original-276.obj"/>
			</geometry>
		</visual>
		<visual name="base_body-13">
			<origin xyz="0 0 0"/>
			<geometry>
				<mesh filename="textured_objs/original-284.obj"/>
			</geometry>
		</visual>
		<visual name="base_body-13">
			<origin xyz="0 0 0"/>
			<geometry>
				<mesh filename="textured_objs/original-90.obj"/>
			</geometry>
		</visual>
		<visual name="base_body-13">
			<origin xyz="0 0 0"/>
			<geometry>
				<mesh filename="textured_objs/original-40.obj"/>
			</geometry>
		</visual>
		<visual name="base_body-13">
			<origin xyz="0 0 0"/>
			<geometry>
				<mesh filename="textured_objs/original-266.obj"/>
			</geometry>
		</visual>
		<visual name="base_body-13">
			<origin xyz="0 0 0"/>
			<geometry>
				<mesh filename="textured_objs/original-143.obj"/>
			</geometry>
		</visual>
		<visual name="base_body-13">
			<origin xyz="0 0 0"/>
			<geometry>
				<mesh filename="textured_objs/original-151.obj"/>
			</geometry>
		</visual>
		<visual name="base_body-13">
			<origin xyz="0 0 0"/>
			<geometry>
				<mesh filename="textured_objs/original-46.obj"/>
			</geometry>
		</visual>
		<visual name="base_body-13">
			<origin xyz="0 0 0"/>
			<geometry>
				<mesh filename="textured_objs/original-238.obj"/>
			</geometry>
		</visual>
		<visual name="base_body-13">
			<origin xyz="0 0 0"/>
			<geometry>
				<mesh filename="textured_objs/original-248.obj"/>
			</geometry>
		</visual>
		<visual name="base_body-13">
			<origin xyz="0 0 0"/>
			<geometry>
				<mesh filename="textured_objs/original-256.obj"/>
			</geometry>
		</visual>
		<visual name="base_body-13">
			<origin xyz="0 0 0"/>
			<geometry>
				<mesh filename="textured_objs/original-176.obj"/>
			</geometry>
		</visual>
		<visual name="base_body-13">
			<origin xyz="0 0 0"/>
			<geometry>
				<mesh filename="textured_objs/original-164.obj"/>
			</geometry>
		</visual>
		<collision>
			<origin xyz="0 0 0"/>
			<geometry>
				<mesh filename="textured_objs/original-29.obj"/>
			</geometry>
		</collision>
		<collision>
			<origin xyz="0 0 0"/>
			<geometry>
				<mesh filename="textured_objs/original-103.obj"/>
			</geometry>
		</collision>
		<collision>
			<origin xyz="0 0 0"/>
			<geometry>
				<mesh filename="textured_objs/original-100.obj"/>
			</geometry>
		</collision>
		<collision>
			<origin xyz="0 0 0"/>
			<geometry>
				<mesh filename="textured_objs/original-123.obj"/>
			</geometry>
		</collision>
		<collision>
			<origin xyz="0 0 0"/>
			<geometry>
				<mesh filename="textured_objs/original-21.obj"/>
			</geometry>
		</collision>
		<collision>
			<origin xyz="0 0 0"/>
			<geometry>
				<mesh filename="textured_objs/original-208.obj"/>
			</geometry>
		</collision>
		<collision>
			<origin xyz="0 0 0"/>
			<geometry>
				<mesh filename="textured_objs/original-30.obj"/>
			</geometry>
		</collision>
		<collision>
			<origin xyz="0 0 0"/>
			<geometry>
				<mesh filename="textured_objs/original-152.obj"/>
			</geometry>
		</collision>
		<collision>
			<origin xyz="0 0 0"/>
			<geometry>
				<mesh filename="textured_objs/original-132.obj"/>
			</geometry>
		</collision>
		<collision>
			<origin xyz="0 0 0"/>
			<geometry>
				<mesh filename="textured_objs/original-236.obj"/>
			</geometry>
		</collision>
		<collision>
			<origin xyz="0 0 0"/>
			<geometry>
				<mesh filename="textured_objs/original-36.obj"/>
			</geometry>
		</collision>
		<collision>
			<origin xyz="0 0 0"/>
			<geometry>
				<mesh filename="textured_objs/original-154.obj"/>
			</geometry>
		</collision>
		<collision>
			<origin xyz="0 0 0"/>
			<geometry>
				<mesh filename="textured_objs/original-249.obj"/>
			</geometry>
		</collision>
		<collision>
			<origin xyz="0 0 0"/>
			<geometry>
				<mesh filename="textured_objs/original-126.obj"/>
			</geometry>
		</collision>
		<collision>
			<origin xyz="0 0 0"/>
			<geometry>
				<mesh filename="textured_objs/original-169.obj"/>
			</geometry>
		</collision>
		<collision>
			<origin xyz="0 0 0"/>
			<geometry>
				<mesh filename="textured_objs/original-198.obj"/>
			</geometry>
		</collision>
		<collision>
			<origin xyz="0 0 0"/>
			<geometry>
				<mesh filename="textured_objs/original-278.obj"/>
			</geometry>
		</collision>
		<collision>
			<origin xyz="0 0 0"/>
			<geometry>
				<mesh filename="textured_objs/original-119.obj"/>
			</geometry>
		</collision>
		<collision>
			<origin xyz="0 0 0"/>
			<geometry>
				<mesh filename="textured_objs/original-188.obj"/>
			</geometry>
		</collision>
		<collision>
			<origin xyz="0 0 0"/>
			<geometry>
				<mesh filename="textured_objs/original-28.obj"/>
			</geometry>
		</collision>
		<collision>
			<origin xyz="0 0 0"/>
			<geometry>
				<mesh filename="textured_objs/original-283.obj"/>
			</geometry>
		</collision>
		<collision>
			<origin xyz="0 0 0"/>
			<geometry>
				<mesh filename="textured_objs/original-124.obj"/>
			</geometry>
		</collision>
		<collision>
			<origin xyz="0 0 0"/>
			<geometry>
				<mesh filename="textured_objs/original-230.obj"/>
			</geometry>
		</collision>
		<collision>
			<origin xyz="0 0 0"/>
			<geometry>
				<mesh filename="textured_objs/original-166.obj"/>
			</geometry>
		</collision>
		<collision>
			<origin xyz="0 0 0"/>
			<geometry>
				<mesh filename="textured_objs/original-224.obj"/>
			</geometry>
		</collision>
		<collision>
			<origin xyz="0 0 0"/>
			<geometry>
				<mesh filename="textured_objs/original-195.obj"/>
			</geometry>
		</collision>
		<collision>
			<origin xyz="0 0 0"/>
			<geometry>
				<mesh filename="textured_objs/original-64.obj"/>
			</geometry>
		</collision>
		<collision>
			<origin xyz="0 0 0"/>
			<geometry>
				<mesh filename="textured_objs/original-134.obj"/>
			</geometry>
		</collision>
		<collision>
			<origin xyz="0 0 0"/>
			<geometry>
				<mesh filename="textured_objs/original-263.obj"/>
			</geometry>
		</collision>
		<collision>
			<origin xyz="0 0 0"/>
			<geometry>
				<mesh filename="textured_objs/original-192.obj"/>
			</geometry>
		</collision>
		<collision>
			<origin xyz="0 0 0"/>
			<geometry>
				<mesh filename="textured_objs/original-43.obj"/>
			</geometry>
		</collision>
		<collision>
			<origin xyz="0 0 0"/>
			<geometry>
				<mesh filename="textured_objs/original-167.obj"/>
			</geometry>
		</collision>
		<collision>
			<origin xyz="0 0 0"/>
			<geometry>
				<mesh filename="textured_objs/original-272.obj"/>
			</geometry>
		</collision>
		<collision>
			<origin xyz="0 0 0"/>
			<geometry>
				<mesh filename="textured_objs/original-193.obj"/>
			</geometry>
		</collision>
		<collision>
			<origin xyz="0 0 0"/>
			<geometry>
				<mesh filename="textured_objs/original-196.obj"/>
			</geometry>
		</collision>
		<collision>
			<origin xyz="0 0 0"/>
			<geometry>
				<mesh filename="textured_objs/original-199.obj"/>
			</geometry>
		</collision>
		<collision>
			<origin xyz="0 0 0"/>
			<geometry>
				<mesh filename="textured_objs/original-83.obj"/>
			</geometry>
		</collision>
		<collision>
			<origin xyz="0 0 0"/>
			<geometry>
				<mesh filename="textured_objs/original-117.obj"/>
			</geometry>
		</collision>
		<collision>
			<origin xyz="0 0 0"/>
			<geometry>
				<mesh filename="textured_objs/original-110.obj"/>
			</geometry>
		</collision>
		<collision>
			<origin xyz="0 0 0"/>
			<geometry>
				<mesh filename="textured_objs/original-153.obj"/>
			</geometry>
		</collision>
		<collision>
			<origin xyz="0 0 0"/>
			<geometry>
				<mesh filename="textured_objs/original-107.obj"/>
			</geometry>
		</collision>
		<collision>
			<origin xyz="0 0 0"/>
			<geometry>
				<mesh filename="textured_objs/original-160.obj"/>
			</geometry>
		</collision>
		<collision>
			<origin xyz="0 0 0"/>
			<geometry>
				<mesh filename="textured_objs/original-222.obj"/>
			</geometry>
		</collision>
		<collision>
			<origin xyz="0 0 0"/>
			<geometry>
				<mesh filename="textured_objs/original-104.obj"/>
			</geometry>
		</collision>
		<collision>
			<origin xyz="0 0 0"/>
			<geometry>
				<mesh filename="textured_objs/original-4.obj"/>
			</geometry>
		</collision>
		<collision>
			<origin xyz="0 0 0"/>
			<geometry>
				<mesh filename="textured_objs/original-149.obj"/>
			</geometry>
		</collision>
		<collision>
			<origin xyz="0 0 0"/>
			<geometry>
				<mesh filename="textured_objs/original-3.obj"/>
			</geometry>
		</collision>
		<collision>
			<origin xyz="0 0 0"/>
			<geometry>
				<mesh filename="textured_objs/original-128.obj"/>
			</geometry>
		</collision>
		<collision>
			<origin xyz="0 0 0"/>
			<geometry>
				<mesh filename="textured_objs/original-260.obj"/>
			</geometry>
		</collision>
		<collision>
			<origin xyz="0 0 0"/>
			<geometry>
				<mesh filename="textured_objs/original-65.obj"/>
			</geometry>
		</collision>
		<collision>
			<origin xyz="0 0 0"/>
			<geometry>
				<mesh filename="textured_objs/original-130.obj"/>
			</geometry>
		</collision>
		<collision>
			<origin xyz="0 0 0"/>
			<geometry>
				<mesh filename="textured_objs/original-137.obj"/>
			</geometry>
		</collision>
		<collision>
			<origin xyz="0 0 0"/>
			<geometry>
				<mesh filename="textured_objs/original-139.obj"/>
			</geometry>
		</collision>
		<collision>
			<origin xyz="0 0 0"/>
			<geometry>
				<mesh filename="textured_objs/original-44.obj"/>
			</geometry>
		</collision>
		<collision>
			<origin xyz="0 0 0"/>
			<geometry>
				<mesh filename="textured_objs/original-112.obj"/>
			</geometry>
		</collision>
		<collision>
			<origin xyz="0 0 0"/>
			<geometry>
				<mesh filename="textured_objs/original-162.obj"/>
			</geometry>
		</collision>
		<collision>
			<origin xyz="0 0 0"/>
			<geometry>
				<mesh filename="textured_objs/original-106.obj"/>
			</geometry>
		</collision>
		<collision>
			<origin xyz="0 0 0"/>
			<geometry>
				<mesh filename="textured_objs/original-16.obj"/>
			</geometry>
		</collision>
		<collision>
			<origin xyz="0 0 0"/>
			<geometry>
				<mesh filename="textured_objs/original-251.obj"/>
			</geometry>
		</collision>
		<collision>
			<origin xyz="0 0 0"/>
			<geometry>
				<mesh filename="textured_objs/original-86.obj"/>
			</geometry>
		</collision>
		<collision>
			<origin xyz="0 0 0"/>
			<geometry>
				<mesh filename="textured_objs/original-173.obj"/>
			</geometry>
		</collision>
		<collision>
			<origin xyz="0 0 0"/>
			<geometry>
				<mesh filename="textured_objs/original-140.obj"/>
			</geometry>
		</collision>
		<collision>
			<origin xyz="0 0 0"/>
			<geometry>
				<mesh filename="textured_objs/original-147.obj"/>
			</geometry>
		</collision>
		<collision>
			<origin xyz="0 0 0"/>
			<geometry>
				<mesh filename="textured_objs/original-109.obj"/>
			</geometry>
		</collision>
		<collision>
			<origin xyz="0 0 0"/>
			<geometry>
				<mesh filename="textured_objs/original-259.obj"/>
			</geometry>
		</collision>
		<collision>
			<origin xyz="0 0 0"/>
			<geometry>
				<mesh filename="textured_objs/original-13.obj"/>
			</geometry>
		</collision>
		<collision>
			<origin xyz="0 0 0"/>
			<geometry>
				<mesh filename="textured_objs/original-210.obj"/>
			</geometry>
		</collision>
		<collision>
			<origin xyz="0 0 0"/>
			<geometry>
				<mesh filename="textured_objs/original-268.obj"/>
			</geometry>
		</collision>
		<collision>
			<origin xyz="0 0 0"/>
			<geometry>
				<mesh filename="textured_objs/original-9.obj"/>
			</geometry>
		</collision>
		<collision>
			<origin xyz="0 0 0"/>
			<geometry>
				<mesh filename="textured_objs/original-125.obj"/>
			</geometry>
		</collision>
		<collision>
			<origin xyz="0 0 0"/>
			<geometry>
				<mesh filename="textured_objs/original-35.obj"/>
			</geometry>
		</collision>
		<collision>
			<origin xyz="0 0 0"/>
			<geometry>
				<mesh filename="textured_objs/original-267.obj"/>
			</geometry>
		</collision>
		<collision>
			<origin xyz="0 0 0"/>
			<geometry>
				<mesh filename="textured_objs/original-279.obj"/>
			</geometry>
		</collision>
		<collision>
			<origin xyz="0 0 0"/>
			<geometry>
				<mesh filename="textured_objs/original-138.obj"/>
			</geometry>
		</collision>
		<collision>
			<origin xyz="0 0 0"/>
			<geometry>
				<mesh filename="textured_objs/original-156.obj"/>
			</geometry>
		</collision>
		<collision>
			<origin xyz="0 0 0"/>
			<geometry>
				<mesh filename="textured_objs/original-201.obj"/>
			</geometry>
		</collision>
		<collision>
			<origin xyz="0 0 0"/>
			<geometry>
				<mesh filename="textured_objs/original-286.obj"/>
			</geometry>
		</collision>
		<collision>
			<origin xyz="0 0 0"/>
			<geometry>
				<mesh filename="textured_objs/original-184.obj"/>
			</geometry>
		</collision>
		<collision>
			<origin xyz="0 0 0"/>
			<geometry>
				<mesh filename="textured_objs/original-144.obj"/>
			</geometry>
		</collision>
		<collision>
			<origin xyz="0 0 0"/>
			<geometry>
				<mesh filename="textured_objs/original-255.obj"/>
			</geometry>
		</collision>
		<collision>
			<origin xyz="0 0 0"/>
			<geometry>
				<mesh filename="textured_objs/original-120.obj"/>
			</geometry>
		</collision>
		<collision>
			<origin xyz="0 0 0"/>
			<geometry>
				<mesh filename="textured_objs/original-59.obj"/>
			</geometry>
		</collision>
		<collision>
			<origin xyz="0 0 0"/>
			<geometry>
				<mesh filename="textured_objs/original-114.obj"/>
			</geometry>
		</collision>
		<collision>
			<origin xyz="0 0 0"/>
			<geometry>
				<mesh filename="textured_objs/original-275.obj"/>
			</geometry>
		</collision>
		<collision>
			<origin xyz="0 0 0"/>
			<geometry>
				<mesh filename="textured_objs/original-241.obj"/>
			</geometry>
		</collision>
		<collision>
			<origin xyz="0 0 0"/>
			<geometry>
				<mesh filename="textured_objs/original-223.obj"/>
			</geometry>
		</collision>
		<collision>
			<origin xyz="0 0 0"/>
			<geometry>
				<mesh filename="textured_objs/original-150.obj"/>
			</geometry>
		</collision>
		<collision>
			<origin xyz="0 0 0"/>
			<geometry>
				<mesh filename="textured_objs/original-239.obj"/>
			</geometry>
		</collision>
		<collision>
			<origin xyz="0 0 0"/>
			<geometry>
				<mesh filename="textured_objs/original-221.obj"/>
			</geometry>
		</collision>
		<collision>
			<origin xyz="0 0 0"/>
			<geometry>
				<mesh filename="textured_objs/original-168.obj"/>
			</geometry>
		</collision>
		<collision>
			<origin xyz="0 0 0"/>
			<geometry>
				<mesh filename="textured_objs/original-63.obj"/>
			</geometry>
		</collision>
		<collision>
			<origin xyz="0 0 0"/>
			<geometry>
				<mesh filename="textured_objs/original-214.obj"/>
			</geometry>
		</collision>
		<collision>
			<origin xyz="0 0 0"/>
			<geometry>
				<mesh filename="textured_objs/original-240.obj"/>
			</geometry>
		</collision>
		<collision>
			<origin xyz="0 0 0"/>
			<geometry>
				<mesh filename="textured_objs/original-185.obj"/>
			</geometry>
		</collision>
		<collision>
			<origin xyz="0 0 0"/>
			<geometry>
				<mesh filename="textured_objs/original-217.obj"/>
			</geometry>
		</collision>
		<collision>
			<origin xyz="0 0 0"/>
			<geometry>
				<mesh filename="textured_objs/original-261.obj"/>
			</geometry>
		</collision>
		<collision>
			<origin xyz="0 0 0"/>
			<geometry>
				<mesh filename="textured_objs/original-27.obj"/>
			</geometry>
		</collision>
		<collision>
			<origin xyz="0 0 0"/>
			<geometry>
				<mesh filename="textured_objs/original-159.obj"/>
			</geometry>
		</collision>
		<collision>
			<origin xyz="0 0 0"/>
			<geometry>
				<mesh filename="textured_objs/original-247.obj"/>
			</geometry>
		</collision>
		<collision>
			<origin xyz="0 0 0"/>
			<geometry>
				<mesh filename="textured_objs/original-170.obj"/>
			</geometry>
		</collision>
		<collision>
			<origin xyz="0 0 0"/>
			<geometry>
				<mesh filename="textured_objs/original-269.obj"/>
			</geometry>
		</collision>
		<collision>
			<origin xyz="0 0 0"/>
			<geometry>
				<mesh filename="textured_objs/original-216.obj"/>
			</geometry>
		</collision>
		<collision>
			<origin xyz="0 0 0"/>
			<geometry>
				<mesh filename="textured_objs/original-87.obj"/>
			</geometry>
		</collision>
		<collision>
			<origin xyz="0 0 0"/>
			<geometry>
				<mesh filename="textured_objs/original-51.obj"/>
			</geometry>
		</collision>
		<collision>
			<origin xyz="0 0 0"/>
			<geometry>
				<mesh filename="textured_objs/original-212.obj"/>
			</geometry>
		</collision>
		<collision>
			<origin xyz="0 0 0"/>
			<geometry>
				<mesh filename="textured_objs/original-163.obj"/>
			</geometry>
		</collision>
		<collision>
			<origin xyz="0 0 0"/>
			<geometry>
				<mesh filename="textured_objs/original-113.obj"/>
			</geometry>
		</collision>
		<collision>
			<origin xyz="0 0 0"/>
			<geometry>
				<mesh filename="textured_objs/original-237.obj"/>
			</geometry>
		</collision>
		<collision>
			<origin xyz="0 0 0"/>
			<geometry>
				<mesh filename="textured_objs/original-50.obj"/>
			</geometry>
		</collision>
		<collision>
			<origin xyz="0 0 0"/>
			<geometry>
				<mesh filename="textured_objs/original-141.obj"/>
			</geometry>
		</collision>
		<collision>
			<origin xyz="0 0 0"/>
			<geometry>
				<mesh filename="textured_objs/original-213.obj"/>
			</geometry>
		</collision>
		<collision>
			<origin xyz="0 0 0"/>
			<geometry>
				<mesh filename="textured_objs/original-111.obj"/>
			</geometry>
		</collision>
		<collision>
			<origin xyz="0 0 0"/>
			<geometry>
				<mesh filename="textured_objs/original-282.obj"/>
			</geometry>
		</collision>
		<collision>
			<origin xyz="0 0 0"/>
			<geometry>
				<mesh filename="textured_objs/original-245.obj"/>
			</geometry>
		</collision>
		<collision>
			<origin xyz="0 0 0"/>
			<geometry>
				<mesh filename="textured_objs/original-287.obj"/>
			</geometry>
		</collision>
		<collision>
			<origin xyz="0 0 0"/>
			<geometry>
				<mesh filename="textured_objs/original-244.obj"/>
			</geometry>
		</collision>
		<collision>
			<origin xyz="0 0 0"/>
			<geometry>
				<mesh filename="textured_objs/original-31.obj"/>
			</geometry>
		</collision>
		<collision>
			<origin xyz="0 0 0"/>
			<geometry>
				<mesh filename="textured_objs/original-187.obj"/>
			</geometry>
		</collision>
		<collision>
			<origin xyz="0 0 0"/>
			<geometry>
				<mesh filename="textured_objs/original-218.obj"/>
			</geometry>
		</collision>
		<collision>
			<origin xyz="0 0 0"/>
			<geometry>
				<mesh filename="textured_objs/original-178.obj"/>
			</geometry>
		</collision>
		<collision>
			<origin xyz="0 0 0"/>
			<geometry>
				<mesh filename="textured_objs/original-37.obj"/>
			</geometry>
		</collision>
		<collision>
			<origin xyz="0 0 0"/>
			<geometry>
				<mesh filename="textured_objs/original-48.obj"/>
			</geometry>
		</collision>
		<collision>
			<origin xyz="0 0 0"/>
			<geometry>
				<mesh filename="textured_objs/original-15.obj"/>
			</geometry>
		</collision>
		<collision>
			<origin xyz="0 0 0"/>
			<geometry>
				<mesh filename="textured_objs/original-85.obj"/>
			</geometry>
		</collision>
		<collision>
			<origin xyz="0 0 0"/>
			<geometry>
				<mesh filename="textured_objs/original-258.obj"/>
			</geometry>
		</collision>
		<collision>
			<origin xyz="0 0 0"/>
			<geometry>
				<mesh filename="textured_objs/original-177.obj"/>
			</geometry>
		</collision>
		<collision>
			<origin xyz="0 0 0"/>
			<geometry>
				<mesh filename="textured_objs/original-122.obj"/>
			</geometry>
		</collision>
		<collision>
			<origin xyz="0 0 0"/>
			<geometry>
				<mesh filename="textured_objs/original-219.obj"/>
			</geometry>
		</collision>
		<collision>
			<origin xyz="0 0 0"/>
			<geometry>
				<mesh filename="textured_objs/original-135.obj"/>
			</geometry>
		</collision>
		<collision>
			<origin xyz="0 0 0"/>
			<geometry>
				<mesh filename="textured_objs/original-76.obj"/>
			</geometry>
		</collision>
		<collision>
			<origin xyz="0 0 0"/>
			<geometry>
				<mesh filename="textured_objs/original-108.obj"/>
			</geometry>
		</collision>
		<collision>
			<origin xyz="0 0 0"/>
			<geometry>
				<mesh filename="textured_objs/original-175.obj"/>
			</geometry>
		</collision>
		<collision>
			<origin xyz="0 0 0"/>
			<geometry>
				<mesh filename="textured_objs/original-186.obj"/>
			</geometry>
		</collision>
		<collision>
			<origin xyz="0 0 0"/>
			<geometry>
				<mesh filename="textured_objs/original-253.obj"/>
			</geometry>
		</collision>
		<collision>
			<origin xyz="0 0 0"/>
			<geometry>
				<mesh filename="textured_objs/original-207.obj"/>
			</geometry>
		</collision>
		<collision>
			<origin xyz="0 0 0"/>
			<geometry>
				<mesh filename="textured_objs/original-99.obj"/>
			</geometry>
		</collision>
		<collision>
			<origin xyz="0 0 0"/>
			<geometry>
				<mesh filename="textured_objs/original-136.obj"/>
			</geometry>
		</collision>
		<collision>
			<origin xyz="0 0 0"/>
			<geometry>
				<mesh filename="textured_objs/original-243.obj"/>
			</geometry>
		</collision>
		<collision>
			<origin xyz="0 0 0"/>
			<geometry>
				<mesh filename="textured_objs/original-127.obj"/>
			</geometry>
		</collision>
		<collision>
			<origin xyz="0 0 0"/>
			<geometry>
				<mesh filename="textured_objs/original-62.obj"/>
			</geometry>
		</collision>
		<collision>
			<origin xyz="0 0 0"/>
			<geometry>
				<mesh filename="textured_objs/original-75.obj"/>
			</geometry>
		</collision>
		<collision>
			<origin xyz="0 0 0"/>
			<geometry>
				<mesh filename="textured_objs/original-174.obj"/>
			</geometry>
		</collision>
		<collision>
			<origin xyz="0 0 0"/>
			<geometry>
				<mesh filename="textured_objs/original-274.obj"/>
			</geometry>
		</collision>
		<collision>
			<origin xyz="0 0 0"/>
			<geometry>
				<mesh filename="textured_objs/original-227.obj"/>
			</geometry>
		</collision>
		<collision>
			<origin xyz="0 0 0"/>
			<geometry>
				<mesh filename="textured_objs/original-254.obj"/>
			</geometry>
		</collision>
		<collision>
			<origin xyz="0 0 0"/>
			<geometry>
				<mesh filename="textured_objs/original-209.obj"/>
			</geometry>
		</collision>
		<collision>
			<origin xyz="0 0 0"/>
			<geometry>
				<mesh filename="textured_objs/original-158.obj"/>
			</geometry>
		</collision>
		<collision>
			<origin xyz="0 0 0"/>
			<geometry>
				<mesh filename="textured_objs/original-66.obj"/>
			</geometry>
		</collision>
		<collision>
			<origin xyz="0 0 0"/>
			<geometry>
				<mesh filename="textured_objs/original-182.obj"/>
			</geometry>
		</collision>
		<collision>
			<origin xyz="0 0 0"/>
			<geometry>
				<mesh filename="textured_objs/original-226.obj"/>
			</geometry>
		</collision>
		<collision>
			<origin xyz="0 0 0"/>
			<geometry>
				<mesh filename="textured_objs/original-211.obj"/>
			</geometry>
		</collision>
		<collision>
			<origin xyz="0 0 0"/>
			<geometry>
				<mesh filename="textured_objs/original-58.obj"/>
			</geometry>
		</collision>
		<collision>
			<origin xyz="0 0 0"/>
			<geometry>
				<mesh filename="textured_objs/original-145.obj"/>
			</geometry>
		</collision>
		<collision>
			<origin xyz="0 0 0"/>
			<geometry>
				<mesh filename="textured_objs/original-98.obj"/>
			</geometry>
		</collision>
		<collision>
			<origin xyz="0 0 0"/>
			<geometry>
				<mesh filename="textured_objs/original-11.obj"/>
			</geometry>
		</collision>
		<collision>
			<origin xyz="0 0 0"/>
			<geometry>
				<mesh filename="textured_objs/original-131.obj"/>
			</geometry>
		</collision>
		<collision>
			<origin xyz="0 0 0"/>
			<geometry>
				<mesh filename="textured_objs/original-242.obj"/>
			</geometry>
		</collision>
		<collision>
			<origin xyz="0 0 0"/>
			<geometry>
				<mesh filename="textured_objs/original-68.obj"/>
			</geometry>
		</collision>
		<collision>
			<origin xyz="0 0 0"/>
			<geometry>
				<mesh filename="textured_objs/original-146.obj"/>
			</geometry>
		</collision>
		<collision>
			<origin xyz="0 0 0"/>
			<geometry>
				<mesh filename="textured_objs/original-80.obj"/>
			</geometry>
		</collision>
		<collision>
			<origin xyz="0 0 0"/>
			<geometry>
				<mesh filename="textured_objs/original-235.obj"/>
			</geometry>
		</collision>
		<collision>
			<origin xyz="0 0 0"/>
			<geometry>
				<mesh filename="textured_objs/original-264.obj"/>
			</geometry>
		</collision>
		<collision>
			<origin xyz="0 0 0"/>
			<geometry>
				<mesh filename="textured_objs/original-190.obj"/>
			</geometry>
		</collision>
		<collision>
			<origin xyz="0 0 0"/>
			<geometry>
				<mesh filename="textured_objs/original-18.obj"/>
			</geometry>
		</collision>
		<collision>
			<origin xyz="0 0 0"/>
			<geometry>
				<mesh filename="textured_objs/original-70.obj"/>
			</geometry>
		</collision>
		<collision>
			<origin xyz="0 0 0"/>
			<geometry>
				<mesh filename="textured_objs/original-161.obj"/>
			</geometry>
		</collision>
		<collision>
			<origin xyz="0 0 0"/>
			<geometry>
				<mesh filename="textured_objs/original-189.obj"/>
			</geometry>
		</collision>
		<collision>
			<origin xyz="0 0 0"/>
			<geometry>
				<mesh filename="textured_objs/original-118.obj"/>
			</geometry>
		</collision>
		<collision>
			<origin xyz="0 0 0"/>
			<geometry>
				<mesh filename="textured_objs/original-225.obj"/>
			</geometry>
		</collision>
		<collision>
			<origin xyz="0 0 0"/>
			<geometry>
				<mesh filename="textured_objs/original-91.obj"/>
			</geometry>
		</collision>
		<collision>
			<origin xyz="0 0 0"/>
			<geometry>
				<mesh filename="textured_objs/original-203.obj"/>
			</geometry>
		</collision>
		<collision>
			<origin xyz="0 0 0"/>
			<geometry>
				<mesh filename="textured_objs/original-250.obj"/>
			</geometry>
		</collision>
		<collision>
			<origin xyz="0 0 0"/>
			<geometry>
				<mesh filename="textured_objs/original-17.obj"/>
			</geometry>
		</collision>
		<collision>
			<origin xyz="0 0 0"/>
			<geometry>
				<mesh filename="textured_objs/original-202.obj"/>
			</geometry>
		</collision>
		<collision>
			<origin xyz="0 0 0"/>
			<geometry>
				<mesh filename="textured_objs/original-12.obj"/>
			</geometry>
		</collision>
		<collision>
			<origin xyz="0 0 0"/>
			<geometry>
				<mesh filename="textured_objs/original-277.obj"/>
			</geometry>
		</collision>
		<collision>
			<origin xyz="0 0 0"/>
			<geometry>
				<mesh filename="textured_objs/original-183.obj"/>
			</geometry>
		</collision>
		<collision>
			<origin xyz="0 0 0"/>
			<geometry>
				<mesh filename="textured_objs/original-281.obj"/>
			</geometry>
		</collision>
		<collision>
			<origin xyz="0 0 0"/>
			<geometry>
				<mesh filename="textured_objs/original-265.obj"/>
			</geometry>
		</collision>
		<collision>
			<origin xyz="0 0 0"/>
			<geometry>
				<mesh filename="textured_objs/original-228.obj"/>
			</geometry>
		</collision>
		<collision>
			<origin xyz="0 0 0"/>
			<geometry>
				<mesh filename="textured_objs/original-171.obj"/>
			</geometry>
		</collision>
		<collision>
			<origin xyz="0 0 0"/>
			<geometry>
				<mesh filename="textured_objs/original-142.obj"/>
			</geometry>
		</collision>
		<collision>
			<origin xyz="0 0 0"/>
			<geometry>
				<mesh filename="textured_objs/original-42.obj"/>
			</geometry>
		</collision>
		<collision>
			<origin xyz="0 0 0"/>
			<geometry>
				<mesh filename="textured_objs/original-79.obj"/>
			</geometry>
		</collision>
		<collision>
			<origin xyz="0 0 0"/>
			<geometry>
				<mesh filename="textured_objs/original-257.obj"/>
			</geometry>
		</collision>
		<collision>
			<origin xyz="0 0 0"/>
			<geometry>
				<mesh filename="textured_objs/original-165.obj"/>
			</geometry>
		</collision>
		<collision>
			<origin xyz="0 0 0"/>
			<geometry>
				<mesh filename="textured_objs/original-102.obj"/>
			</geometry>
		</collision>
		<collision>
			<origin xyz="0 0 0"/>
			<geometry>
				<mesh filename="textured_objs/original-20.obj"/>
			</geometry>
		</collision>
		<collision>
			<origin xyz="0 0 0"/>
			<geometry>
				<mesh filename="textured_objs/original-88.obj"/>
			</geometry>
		</collision>
		<collision>
			<origin xyz="0 0 0"/>
			<geometry>
				<mesh filename="textured_objs/original-191.obj"/>
			</geometry>
		</collision>
		<collision>
			<origin xyz="0 0 0"/>
			<geometry>
				<mesh filename="textured_objs/original-32.obj"/>
			</geometry>
		</collision>
		<collision>
			<origin xyz="0 0 0"/>
			<geometry>
				<mesh filename="textured_objs/original-47.obj"/>
			</geometry>
		</collision>
		<collision>
			<origin xyz="0 0 0"/>
			<geometry>
				<mesh filename="textured_objs/original-206.obj"/>
			</geometry>
		</collision>
		<collision>
			<origin xyz="0 0 0"/>
			<geometry>
				<mesh filename="textured_objs/original-95.obj"/>
			</geometry>
		</collision>
		<collision>
			<origin xyz="0 0 0"/>
			<geometry>
				<mesh filename="textured_objs/original-197.obj"/>
			</geometry>
		</collision>
		<collision>
			<origin xyz="0 0 0"/>
			<geometry>
				<mesh filename="textured_objs/original-200.obj"/>
			</geometry>
		</collision>
		<collision>
			<origin xyz="0 0 0"/>
			<geometry>
				<mesh filename="textured_objs/original-105.obj"/>
			</geometry>
		</collision>
		<collision>
			<origin xyz="0 0 0"/>
			<geometry>
				<mesh filename="textured_objs/original-101.obj"/>
			</geometry>
		</collision>
		<collision>
			<origin xyz="0 0 0"/>
			<geometry>
				<mesh filename="textured_objs/original-180.obj"/>
			</geometry>
		</collision>
		<collision>
			<origin xyz="0 0 0"/>
			<geometry>
				<mesh filename="textured_objs/original-1.obj"/>
			</geometry>
		</collision>
		<collision>
			<origin xyz="0 0 0"/>
			<geometry>
				<mesh filename="textured_objs/original-233.obj"/>
			</geometry>
		</collision>
		<collision>
			<origin xyz="0 0 0"/>
			<geometry>
				<mesh filename="textured_objs/original-81.obj"/>
			</geometry>
		</collision>
		<collision>
			<origin xyz="0 0 0"/>
			<geometry>
				<mesh filename="textured_objs/original-84.obj"/>
			</geometry>
		</collision>
		<collision>
			<origin xyz="0 0 0"/>
			<geometry>
				<mesh filename="textured_objs/original-271.obj"/>
			</geometry>
		</collision>
		<collision>
			<origin xyz="0 0 0"/>
			<geometry>
				<mesh filename="textured_objs/original-94.obj"/>
			</geometry>
		</collision>
		<collision>
			<origin xyz="0 0 0"/>
			<geometry>
				<mesh filename="textured_objs/original-280.obj"/>
			</geometry>
		</collision>
		<collision>
			<origin xyz="0 0 0"/>
			<geometry>
				<mesh filename="textured_objs/original-97.obj"/>
			</geometry>
		</collision>
		<collision>
			<origin xyz="0 0 0"/>
			<geometry>
				<mesh filename="textured_objs/original-252.obj"/>
			</geometry>
		</collision>
		<collision>
			<origin xyz="0 0 0"/>
			<geometry>
				<mesh filename="textured_objs/original-157.obj"/>
			</geometry>
		</collision>
		<collision>
			<origin xyz="0 0 0"/>
			<geometry>
				<mesh filename="textured_objs/original-89.obj"/>
			</geometry>
		</collision>
		<collision>
			<origin xyz="0 0 0"/>
			<geometry>
				<mesh filename="textured_objs/original-179.obj"/>
			</geometry>
		</collision>
		<collision>
			<origin xyz="0 0 0"/>
			<geometry>
				<mesh filename="textured_objs/original-10.obj"/>
			</geometry>
		</collision>
		<collision>
			<origin xyz="0 0 0"/>
			<geometry>
				<mesh filename="textured_objs/original-231.obj"/>
			</geometry>
		</collision>
		<collision>
			<origin xyz="0 0 0"/>
			<geometry>
				<mesh filename="textured_objs/original-14.obj"/>
			</geometry>
		</collision>
		<collision>
			<origin xyz="0 0 0"/>
			<geometry>
				<mesh filename="textured_objs/original-232.obj"/>
			</geometry>
		</collision>
		<collision>
			<origin xyz="0 0 0"/>
			<geometry>
				<mesh filename="textured_objs/original-215.obj"/>
			</geometry>
		</collision>
		<collision>
			<origin xyz="0 0 0"/>
			<geometry>
				<mesh filename="textured_objs/original-82.obj"/>
			</geometry>
		</collision>
		<collision>
			<origin xyz="0 0 0"/>
			<geometry>
				<mesh filename="textured_objs/original-129.obj"/>
			</geometry>
		</collision>
		<collision>
			<origin xyz="0 0 0"/>
			<geometry>
				<mesh filename="textured_objs/original-60.obj"/>
			</geometry>
		</collision>
		<collision>
			<origin xyz="0 0 0"/>
			<geometry>
				<mesh filename="textured_objs/original-204.obj"/>
			</geometry>
		</collision>
		<collision>
			<origin xyz="0 0 0"/>
			<geometry>
				<mesh filename="textured_objs/original-229.obj"/>
			</geometry>
		</collision>
		<collision>
			<origin xyz="0 0 0"/>
			<geometry>
				<mesh filename="textured_objs/original-19.obj"/>
			</geometry>
		</collision>
		<collision>
			<origin xyz="0 0 0"/>
			<geometry>
				<mesh filename="textured_objs/original-276.obj"/>
			</geometry>
		</collision>
		<collision>
			<origin xyz="0 0 0"/>
			<geometry>
				<mesh filename="textured_objs/original-284.obj"/>
			</geometry>
		</collision>
		<collision>
			<origin xyz="0 0 0"/>
			<geometry>
				<mesh filename="textured_objs/original-90.obj"/>
			</geometry>
		</collision>
		<collision>
			<origin xyz="0 0 0"/>
			<geometry>
				<mesh filename="textured_objs/original-40.obj"/>
			</geometry>
		</collision>
		<collision>
			<origin xyz="0 0 0"/>
			<geometry>
				<mesh filename="textured_objs/original-266.obj"/>
			</geometry>
		</collision>
		<collision>
			<origin xyz="0 0 0"/>
			<geometry>
				<mesh filename="textured_objs/original-143.obj"/>
			</geometry>
		</collision>
		<collision>
			<origin xyz="0 0 0"/>
			<geometry>
				<mesh filename="textured_objs/original-151.obj"/>
			</geometry>
		</collision>
		<collision>
			<origin xyz="0 0 0"/>
			<geometry>
				<mesh filename="textured_objs/original-46.obj"/>
			</geometry>
		</collision>
		<collision>
			<origin xyz="0 0 0"/>
			<geometry>
				<mesh filename="textured_objs/original-238.obj"/>
			</geometry>
		</collision>
		<collision>
			<origin xyz="0 0 0"/>
			<geometry>
				<mesh filename="textured_objs/original-248.obj"/>
			</geometry>
		</collision>
		<collision>
			<origin xyz="0 0 0"/>
			<geometry>
				<mesh filename="textured_objs/original-256.obj"/>
			</geometry>
		</collision>
		<collision>
			<origin xyz="0 0 0"/>
			<geometry>
				<mesh filename="textured_objs/original-176.obj"/>
			</geometry>
		</collision>
		<collision>
			<origin xyz="0 0 0"/>
			<geometry>
				<mesh filename="textured_objs/original-164.obj"/>
			</geometry>
		</collision>
	</link>
	<joint name="joint_11" type="fixed">
		<origin rpy="1.570796326794897 0 -1.570796326794897" xyz="0 0 0"/>
		<child link="link_11"/>
		<parent link="base"/>
	</joint>
</robot>
