<?xml version="1.0" ?>
<robot name="partnet_1252e89db37d786386d53ab0fe94e911">
	<link name="base"/>
	<link name="link_0">
		<visual name="handle-16">
			<origin xyz="0.37263062667115143 0.5667060017585756 -0.5220061005381347"/>
			<geometry>
				<mesh filename="textured_objs/link_0.obj"/>
			</geometry>
		</visual>
		<collision>
			<origin xyz="0.37263062667115143 0.5667060017585756 -0.5220061005381347"/>
			<geometry>
				<mesh filename="textured_objs/link_0_convex.obj"/>
			</geometry>
		</collision>
	</link>
	<link name="link_1">
		<visual name="drawer_front-9">
			<origin xyz="0.017042793320627622 -0.5967289342718265 0.5155950188636786"/>
			<geometry>
				<mesh filename="textured_objs/link_1.obj"/>
			</geometry>
		</visual>
		<collision>
			<origin xyz="0.017042793320627622 -0.5967289342718265 0.5155950188636786"/>
			<geometry>
				<mesh filename="textured_objs/link_1_convex.obj"/>
			</geometry>
		</collision>
	</link>
	<link name="link_2">
		<visual name="shelf-4">
			<origin xyz="0 0 0"/>
			<geometry>
				<mesh filename="textured_objs/link_2.obj"/>
			</geometry>
		</visual>
		<collision>
			<origin xyz="0 0 0"/>
			<geometry>
				<mesh filename="textured_objs/link_2_convex.obj"/>
			</geometry>
		</collision>
	</link>
	<joint name="joint_0" type="revolute">
		<origin xyz="-0.37263062667115143 -0.5667060017585756 0.5220061005381347"/>
		<axis xyz="0 -1 0"/>
		<child link="link_0"/>
		<parent link="link_2"/>
		<limit lower="0.0" upper="1.5707963267948966"/>
		<dynamics damping="0.0002" friction="0.01"/>
	</joint>
	<joint name="joint_1" type="prismatic">
		<origin xyz="-0.017042793320627622 0.5967289342718265 -0.5155950188636786"/>
		<axis xyz="0 0 1"/>
		<child link="link_1"/>
		<parent link="link_2"/>
		<limit lower="0" upper="0.7999999999999998"/>
		<dynamics damping="0.0002" friction="0.01"/>
	</joint>
	<joint name="joint_2" type="fixed">
		<origin rpy="1.570796326794897 0 -1.570796326794897" xyz="0 0 0"/>
		<child link="link_2"/>
		<parent link="base"/>
		<dynamics damping="0.0002" friction="0.01"/>
	</joint>
</robot>